********* Start testing of tst_VerifyExceptionThrown *********
Config: Using QtTest library @INSERT_QT_VERSION_HERE@, Qt @INSERT_QT_VERSION_HERE@
PASS   : tst_VerifyExceptionThrown::initTestCase()
PASS   : tst_VerifyExceptionThrown::testCorrectStdTypes()
PASS   : tst_VerifyExceptionThrown::testCorrectStdExceptions()
PASS   : tst_VerifyExceptionThrown::testCorrectMyExceptions()
FAIL!  : tst_VerifyExceptionThrown::testFailInt() Expected exception of type double to be thrown but unknown exception caught
   Loc: [tst_verifyexceptionthrown.cpp(128)]
FAIL!  : tst_VerifyExceptionThrown::testFailStdString() Expected exception of type char* to be thrown but unknown exception caught
   Loc: [tst_verifyexceptionthrown.cpp(133)]
FAIL!  : tst_VerifyExceptionThrown::testFailStdRuntimeError() Expected exception of type std::runtime_error to be thrown but std::exception caught with message: logic error
   Loc: [tst_verifyexceptionthrown.cpp(138)]
FAIL!  : tst_VerifyExceptionThrown::testFailMyException() Expected exception of type MyBaseException to be thrown but std::exception caught with message: logic error
   Loc: [tst_verifyexceptionthrown.cpp(143)]
FAIL!  : tst_VerifyExceptionThrown::testFailMyDerivedException() Expected exception of type std::runtime_error to be thrown but std::exception caught with message: MyDerivedException
   Loc: [tst_verifyexceptionthrown.cpp(148)]
FAIL!  : tst_VerifyExceptionThrown::testFailNoException() Expected exception of type std::exception to be thrown but no exception caught
   Loc: [tst_verifyexceptionthrown.cpp(153)]
PASS   : tst_VerifyExceptionThrown::cleanupTestCase()
Totals: 5 passed, 6 failed, 0 skipped, 0 blacklisted
********* Finished testing of tst_VerifyExceptionThrown *********
